Workbook

Sheet Guide
A1: SAFERSEAS Analytics Implementation Guide
A2: Formula-driven Excel companion to the mockup using the same dummy dataset and equivalent transferable visuals.
A4: Purpose
A5: This workbook mirrors the mockup's analytical outputs so a developer can inspect raw data, derived logic, chart helper tables, and policy evidence calculations in Excel.
A7: Included workbook sections
A8: - Raw_Incidents: source dummy data from the mockup
A9: - Lookups: region maps, fallback logic, season order, severity weights
A10: - Enriched: formula-driven derived fields used by analytics
A11: - Trend / Causal / Exposure / Quality sheets: chart helper tables plus Excel charts
A12: - Policy_Brief: policy packets, corridor register, data caveats, methodology notes
A15: Not transferred from the mockup
A16: The interactive GIS density/cluster map is not reproduced as a native Excel visual. The workbook retains the same underlying coordinates and corridor logic, but not the map interaction layer.
... A19: Risk Index and Confidence Score are included because the mockup uses them, but both remain working proxies for implementation guidance, not validated operational doctrine.

Sheet Raw_Incidents
A1: Raw Incident Dataset
A2: Direct export of the current SAFERSEAS dummy dataset.
A4: Incident ID | B4: Incident DateTime | C4: Incident Type | D4: Casualty Type | E4: Severity | F4: Vessel Name | G4: Former Names | H4: Vessel Type | I4: Flag State | J4: IMO Number | K4: Official Number | L4: Gross Tonnage | M4: Length Meters | N4: Breadth Meters | O4: Propulsion Type | P4: Engine Power kW | Q4: Classification Society | R4: Year Built | S4: Latitude | T4: Longitude | U4: Reference Port | V4: Province | W4: Sea Area | X4: Corridor | Y4: Wave Height (m) | Z4: Wind Force | AA4: Visibility | AB4: Owner Name | AC4: Owner Contact | AD4: Operator Name | AE4: Operator Address | AF4: Voyage Origin | AG4: Voyage Destination | AH4: Intended Route | AI4: Cargo Type | AJ4: Cargo Quantity | AK4: Authority | AL4: Reporting Method | AM4: Status | AN4: Narrative | AO4: Key Events Timeline | AP4: Crew Response | AQ4: Crew Behavior Factors | AR4: Primary Cause | AS4: Findings Of Cause | AT4: Damages Incurred | AU4: Crew Count | AV4: Passenger Count | AW4: Fatalities | AX4: Injuries | AY4: Recommendations | AZ4: Linked Documents
A5: INC-2025-000101 | B5: 45669.184 | C5: Collision | D5: Injury | E5: Serious | F5: MV Pacific Trader | G5: MV Eastern Star | H5: Bulk Carrier | I5: Philippines | J5: IMO 9482713 | K5: PH-2026-7781 | L5: 25000 | M5: 189.6 | N5: 32.2 | O5: Diesel engine | P5: 11200 | Q5: Bureau Veritas | R5: 2006 | S5: 14.663 | T5: 120.762 | U5: Manila | V5: Metro Manila | W5: Manila Bay | X5: Manila Bay North Approach | Y5: 1.6 | Z5: 4 | AA5: Moderate | AB5: Pacific Shipping Lines | AC5: +63 2 8123 4567 | AD5: Pacific Marine Operations | AE5: Port Area, Manila, Philippines | AF5: Subic | AG5: Manila | AH5: Subic-Manila inbound traffic lane | AI5: Bulk cargo | AJ5: 18,000 MT cement clinker | AK5: MARINA | AL5: Web Portal | AM5: Published | AN5: Bulk carrier made contact with a harbor support craft while inbound to Manila Bay under congested traffic conditions. | AO5: 04:02 pilot boarding; 04:18 crossing traffic advisory; 04:25 contact with harbor support craft near approach lane edge. | AP5: Master reduced speed, sounded danger signal, and coordinated towing assistance for the support craft. | AQ5: Communication Failure | Violation of Procedures | AR5: Navigation Error | AS5: Late course alteration in dense approach traffic reduced passing distance below safe margins. | AT5: Hull Damage | Third-Party Property | AU5: 22 | AV5: 0 | AW5: 0 | AX5: 2 | AY5: Reinforce bridge resource management and pilot-master exchange procedures for Manila Bay approaches. | AZ5: AIS Track | Pilot Exchange Form | Photo Log
A6: INC-2025-000118 | B6: 45685.444 | C6: Fire/Explosion | D6: Injury | E6: Serious | F6: MT Ocean Star | H6: Oil Tanker | I6: Singapore | J6: IMO 9338894 | K6: SG-TK-4218 | L6: 29400 | M6: 183.8 | N6: 32 | O6: Slow-speed marine diesel | P6: 9780 | Q6: Lloyd's Register | R6: 2008 | S6: 13.758 | T6: 121.076 | U6: Batangas | V6: Batangas | W6: Verde Island Passage | X6: Batangas-Calapan Transit Lane | Y6: 1.4 | Z6: 4 | AA6: Good | AB6: Blue Meridian Tankers | AC6: +65 6712 9088 | AD6: Meridian Offshore Management | AE6: Jurong Port Road, Singapore | AF6: Batangas | AG6: Calapan | AH6: Verde Island Passage east-west corridor | AI6: Fuel / Oil | AJ6: 22,500 barrels marine diesel | AK6: MARINA | AL6: Inter-agency Intake | AM6: Under Review | AN6: Localized purifier room fire was contained while the tanker transited the Verde Island Passage. | AO6: 10:21 purifier alarm; 10:29 fire team deployed; 10:40 fire declared contained and cooling commenced. | AP6: Engine room fixed system was placed on standby while boundary cooling and isolation procedures were carried out. | AQ6: Inadequate Training | AR6: Mechanical Failure | AS6: Fuel leakage from a worn seal ignited on contact with a hot surface inside the purifier room. | AT6: Equipment Damage | AU6: 28 | AV6: 0 | AW6: 0 | AX6: 4 | AY6: Increase purifier seal inspection frequency and require pre-transit machinery readiness checks for tankers. | AZ6: Engine Logbook | Class Survey Note | Chief Engineer Statement
A7: INC-2025-000133 | B7: 45694.01 | C7: Grounding | D7: Injury | E7: Serious | F7: MV Island Express | H7: Ferry | I7: Philippines | J7: IMO 9134452 | K7: OFN-55281 | L7: 8450 | M7: 118.4 | N7: 18.3 | O7: Twin diesel propulsion | P7: 6400 | Q7: Nippon Kaiji Kyokai | R7: 2011 | S7: 10.231 | T7: 123.931 | U7: Cebu | V7: Cebu | W7: Cebu Strait | X7: Cebu-Mactan Southern Approach | Y7: 1 | Z7: 3 | AA7: Good | AB7: Island Ferry Holdings | AC7: +63 32 455 1188 | AD7: Island Express Ferries | AE7: Pier 3, Cebu City, Philippines | AF7: Cebu | AG7: Ormoc | AH7: Cebu Strait domestic passenger corridor | AI7: Passengers | AJ7: 187 passengers with accompanied baggage | AK7: PCG | AL7: Mobile App | AM7: Verified | AN7: Passenger ferry grounded on a shoal after deviating slightly south of the recommended approach track. | AO7: 00:02 departure from Cebu channel; 00:11 track drift observed; 00:15 bottom contact and stop. | AP7: Crew initiated passenger briefing, checked void spaces, and coordinated tug support before refloating. | AQ7: Violation of Procedures | AR7: Navigation Error | AS7: The bridge team did not positively verify the cross-track error before altering toward the terminal approach. | AT7: Hull Damage | AU7: 15 | AV7: 187 | AW7: 0 | AX7: 3 | AY7: Require electronic cross-track alarm checks on high-frequency ferry routes in Cebu Strait. | AZ7: ECDIS Replay | Passenger Manifest | Grounding Sketch
A8: INC-2025-000147 | B8: 45706.538 | C8: Person Overboard | D8: Fatality | E8: Serious | F8: MV Visayan Princess | H8: Passenger Vessel | I8: Philippines | J8: IMO 9006173 | K8: PH-PAX-4412 | L8: 6720 | M8: 109.3 | N8: 17.6 | O8: Dual diesel propulsion | P8: 5810 | Q8: RINA | R8: 2009 | S8: 9.696 | T8: 118.491 | U8: Puerto Princesa | V8: Palawan | W8: Palawan Approaches | X8: Puerto Princesa Western Approach | Y8: 1.5 | Z8: 4 | AA8: Good | AB8: Visayan Coastal Lines | AC8: +63 32 332 7777 | AD8: Visayan Passenger Shipping | AE8: North Reclamation Area, Cebu City, Philippines | AF8: Cuyo | AG8: Puerto Princesa | AH8: West Palawan coastal approach lane | AI8: Passengers | AJ8: 126 passengers and light vehicle deck cargo | AK8: PCG | AL8: Email Intake | AM8: Published | AN8: Passenger was reported missing shortly after sunset during the western approach to Puerto Princesa. | AO8: 12:40 passenger unaccounted for; 12:47 muster completed; 12:55 Williamson turn commenced and search initiated. | AP8: Bridge team marked the last-known position, deployed lookouts, and coordinated with the coast station for search support. | AQ8: Fatigue | AR8: Human Error | AS8: Open weather deck access combined with delayed detection extended the response timeline. | AT8: None Reported | AU8: 16 | AV8: 126 | AW8: 1 | AX8: 0 | AY8: Strengthen passenger deck surveillance and tighten restricted-area patrol procedures during night sailing. | AZ8: CCTV Still Frames | Search Track Plot | Passenger List
A9: INC-2025-000163 | B9: 45719.889 | C9: Sinking | D9: Fatality | E9: Very Serious | F9: FB Santa Rosa | H9: Fishing Vessel | I9: Philippines | K9: PH-FV-11892 | L9: 110 | M9: 28.4 | N9: 6.9 | O9: Marine diesel | P9: 540 | R9: 2002 | S9: 10.949 | T9: 125.574 | U9: Liloan | V9: Southern Leyte | W9: Surigao Strait | X9: Liloan-Surigao Crossing | Y9: 3.8 | Z9: 8 | AA9: Poor | AB9: Santa Rosa Fishing Cooperative | AC9: +63 78 889 2121 | AD9: Santa Rosa Fishing Cooperative | AE9: Aparri Fishing Port, Cagayan, Philippines | AF9: Liloan | AG9: Surigao | AH9: Southern Leyte-Surigao strait crossing lane | AI9: Fish Catch | AJ9: 12 MT mixed pelagic catch | AK9: PCG | AL9: Manual Encoding | AM9: Published | AN9: Fishing vessel took repeated boarding seas and sank while crossing the eastern edge of the Surigao Strait traffic lane. | AO9: 20:55 weather deterioration reported; 21:10 progressive flooding; 21:20 vessel abandoned and later sank. | AP9: Crew attempted dewatering and donned lifejackets before abandoning to a nearby banca rescue. | AQ9: Violation of Procedures | Communication Failure | AR9: Weather Conditions | AS9: The vessel continued fishing operations despite fresh gale warnings and an overloaded deck condition. | AT9: Total Loss | AU9: 10 | AV9: 0 | AW9: 3 | AX9: 2 | AY9: Tighten heavy-weather departure controls for small fishing vessels operating across Surigao Strait. | AZ9: Weather Advisory | Rescue Timeline | Witness Statements
A10: INC-2025-000181 | B10: 45732.354 | C10: Capsizing | D10: Fatality | E10: Very Serious | F10: FB San Miguel | H10: Fishing Vessel | I10: Philippines | K10: PH-FV-8743 | L10: 82 | M10: 24.1 | N10: 6.2 | O10: Marine diesel | P10: 430 | R10: 2004 | S10: 6.874 | T10: 125.729 | U10: Davao | V10: Davao del Sur | W10: Davao Gulf | X10: Samal-Davao Pilotage Route | Y10: 3.1 | Z10: 7 | AA10: Moderate | AB10: San Miguel Fisheries | AC10: +63 82 225 9167 | AD10: San Miguel Fisheries | AE10: Davao Fish Port, Davao City, Philippines | AF10: General Santos | AG10: Davao | AH10: Davao Gulf northbound merchant lane | AI10: Fish Catch | AJ10: 7 MT tuna and mixed catch | AK10: PCG | AL10: Mobile App | AM10: Published | AN10: Fishing vessel capsized while hauling gear in beam seas near the northern Davao Gulf lane. | AO10: 08:05 hauling operations started; 08:24 deck load shifted; 08:30 capsize and abandonment. | AP10: Nearby fishing craft recovered survivors while PCG launched a delayed follow-up search. | AQ10: Violation of Procedures | AR10: Weather Conditions | AS10: Uneven gear loading and side-on wave exposure caused a rapid loss of stability. | AT10: Total Loss | AU10: 8 | AV10: 0 | AW10: 2 | AX10: 1 | AY10: Issue stability guidance for ring-net operations and enforce weather-triggered haul suspension in Davao Gulf. | AZ10: Fisheries Permit | Survivor Statement | Search Map
A11: INC-2025-000196 | B11: 45745.243 | C11: Collision | D11: Property Damage | E11: Less Serious | F11: MV Samar Venture | H11: Ferry | I11: Philippines | K11: PH-RORO-5612 | L11: 5120 | M11: 92.2 | N11: 16.7 | O11: Twin screw diesel | P11: 4680 | Q11: Bureau Veritas | R11: 2013 | S11: 12.753 | T11: 124.38 | U11: Matnog | V11: Sorsogon | W11: San Bernardino Strait | X11: Matnog-Allen Ferry Transit | Y11: 1.9 | Z11: 5 | AA11: Moderate | AB11: Eastern Nautical Transport | AC11: +63 56 812 9951 | AD11: Samar Venture Ferries | AE11: Matnog Ferry Terminal, Sorsogon, Philippines | AF11: Matnog | AG11: Allen | AH11: San Bernardino inter-island ferry route | AI11: Passengers | AJ11: 132 passengers and 28 rolling vehicles | AK11: PCG | AL11: Web Portal | AM11: Verified | AN11: RoRo ferry brushed a lightering barge while adjusting its lane position in San Bernardino Strait. | AO11: 05:42 overtaking maneuver started; 05:48 barge altered unexpectedly; 05:50 side contact occurred. | AP11: Master stabilized heading, checked passenger spaces, and escorted the barge clear of the lane. | AQ11: Communication Failure | AR11: Navigation Error | AS11: Insufficient passing communication between the RoRo ferry and barge watchkeepers reduced maneuvering margins. | AT11: Hull Damage | Third-Party Property | AU11: 18 | AV11: 132 | AW11: 0 | AX11: 1 | AY11: Publish overtaking guidance and mandatory bridge-to-bridge phraseology for San Bernardino crossings. | AZ11: VHF Transcript | Damage Photos | Bridge Log
A12: INC-2025-000214 | B12: 45757.066 | C12: Machinery Failure | D12: None | E12: Less Serious | F12: MV Pacific Dream | H12: Bulk Carrier | I12: Marshall Islands | J12: IMO 9440878 | K12: MH-BC-3019 | L12: 27850 | M12: 190.4 | N12: 32.1 | O12: Slow-speed diesel engine | P12: 11860 | Q12: ABS | R12: 2007 | S12: 8.543 | T12: 124.784 | U12: Cagayan de Oro | V12: Misamis Oriental | W12: Macajalar Bay | X12: Macajalar Bay Bulk Access Lane | Y12: 0.9 | Z12: 3 | AA12: Good | AB12: TransPacific Dry Bulk | AC12: +692 625 9911 | AD12: TransPacific Marine Services | AE12: Majuro Registry Office | AF12: Iligan | AG12: Cagayan de Oro | AH12: Macajalar Bay industrial shipping lane | AI12: Bulk cargo | AJ12: 20,500 MT clinker and steel billets | AK12: MARINA | AL12: Web Portal | AM12: Verified | AN12: Main engine lube-oil pressure alarm forced the bulk carrier to anchor inside Macajalar Bay. | AO12: 01:18 alarm received; 01:24 engine load reduced; 01:35 emergency anchoring completed. | AP12: Engineering watch shifted to local control while the master coordinated a safe anchorage with the port authority. | AQ12: Inadequate Training | AR12: Mechanical Failure | AS12: A clogged lube-oil filter reduced pressure to a level that triggered protective slowdown. | AT12: Equipment Damage | AU12: 24 | AV12: 0 | AW12: 0 | AX12: 0 | AY12: Require lube-oil filter differential pressure logging before arrival in industrial bay approaches. | AZ12: Engine Alarm Printout | Anchorage Position Plot | Chief Engineer Report
A13: INC-2025-000229 | B13: 45768.295 | C13: Flooding | D13: None | E13: Less Serious | F13: MV Island Hopper | H13: Ferry | I13: Philippines | K13: PH-RORO-2024 | L13: 3960 | M13: 74.6 | N13: 14.1 | O13: Twin diesel propulsion | P13: 3210 | Q13: RINA | R13: 2014 | S13: 10.678 | T13: 122.578 | U13: Iloilo | V13: Iloilo | W13: Iloilo Strait | X13: Iloilo-Guimaras Transit Lane | Y13: 1.3 | Z13: 4 | AA13: Good | AB13: Archipelago Transport Link | AC13: +63 43 288 5221 | AD13: Archipelago Transport Link | AE13: Calapan Port Complex, Oriental Mindoro, Philippines | AF13: Iloilo | AG13: Bacolod | AH13: Panay-Negros coastal ferry lane | AI13: Passengers | AJ13: 82 passengers and 18 light vehicles | AK13: PCG | AL13: Mobile App | AM13: Verified | AN13: Water ingress was detected in a lower void space while the RoRo ferry transited Iloilo Strait. | AO13: 06:49 bilge alarm; 06:57 inspection team dispatched; 07:05 leak source isolated and pumpout started. | AP13: Crew restricted passenger movement, monitored water level, and completed a controlled return to port. | AQ13: Communication Failure | AR13: Mechanical Failure | AS13: A deteriorated sea chest gasket allowed slow water ingress during repeated docking cycles. | AT13: Hull Damage | AU13: 12 | AV13: 82 | AW13: 0 | AX13: 0 | AY13: Increase seal inspection intervals for high-frequency RoRo ferries operating in short strait passages. | AZ13: Void Space Inspection Sheet | Pump Log | Return-to-Port Notice
A14: INC-2025-000246 | B14: 45785.698 | C14: Collision | D14: None | E14: Near Miss | F14: MV Cargo Link | H14: Container Ship | I14: Panama | J14: IMO 9291173 | K14: PA-CS-4421 | L14: 18600 | M14: 172.3 | N14: 27.9 | O14: Diesel engine | P14: 10240 | Q14: DNV | R14: 2010 | S14: 14.37 | T14: 120.873 | U14: Manila | V14: Metro Manila | W14: Manila Bay | X14: Manila Bay South Approach | Y14: 1.1 | Z14: 4 | AA14: Moderate | AB14: Cargo Link Asia Ltd. | AC14: +507 206 8100 | AD14: Cargo Link Shipmanagement | AE14: Panama City, Panama | AF14: Batangas | AG14: Manila | AH14: Batangas-Manila gateway lane | AI14: Containers | AJ14: 1,240 TEU mixed consumer cargo | AK14: MARINA | AL14: Web Portal | AM14: Under Review | AN14: Container ship narrowly avoided contact with a coastal tanker during a crossing situation in southern Manila Bay. | AO14: 16:37 target acquired; 16:42 late course correction; 16:45 minimum CPA recorded at unsafe margin. | AP14: Bridge team executed a hard-to-starboard maneuver and reported the event as a near miss on arrival. | AQ14: Violation of Procedures | Communication Failure | AR14: Navigation Error | AS14: Delayed risk-of-collision assessment reduced the time available for an orderly avoiding action. | AT14: None Reported | AU14: 20 | AV14: 0 | AW14: 0 | AX14: 0 | AY14: Introduce near-miss reporting reviews for Manila Bay crossing traffic to capture precursors before collision events. | AZ14: VDR Event Marker | AIS Replay | Master Near-Miss Report
A15: INC-2025-000264 | B15: 45803.132 | C15: Grounding | D15: Injury | E15: Less Serious | F15: MV Verde Logistics | H15: General Cargo | I15: Philippines | K15: PH-GC-8344 | L15: 5120 | M15: 91.2 | N15: 15.4 | O15: Marine diesel | P15: 4460 | Q15: ClassNK | R15: 2015 | S15: 13.787 | T15: 121.04 | U15: Batangas | V15: Batangas | W15: Verde Island Passage | X15: Batangas-Calapan Transit Lane | Y15: 1.2 | Z15: 3 | AA15: Good | AB15: Verde Coastal Logistics | AC15: +63 43 723 1180 | AD15: Verde Coastal Logistics | AE15: Batangas Port, Batangas, Philippines | AF15: Batangas | AG15: Calapan | AH15: Verde Island Passage east-west corridor | AI15: General Cargo | AJ15: 5,100 MT bagged feed and construction supplies | AK15: PCG | AL15: Inter-agency Intake | AM15: Verified | AN15: General cargo vessel touched bottom on the edge of a reef patch while crossing the Verde Island Passage. | AO15: 02:58 waypoint alteration; 03:06 depth alarm; 03:10 bottom contact and immediate stop. | AP15: Master held position, checked tank soundings, and waited for daylight inspection before refloating. | AQ15: Violation of Procedures | AR15: Navigation Error | AS15: The track line entered a charted shallow patch after the bridge team bypassed a route check in calm conditions. | AT15: Hull Damage | AU15: 16 | AV15: 0 | AW15: 0 | AX15: 1 | AY15: Require route verification checkpoints across the Verde Island Passage regardless of weather conditions. | AZ15: Chart Extract | Sounding Report | Post-Refloat Inspection
A16: INC-2025-000281 | B16: 45819.403 | C16: Collision | D16: Injury | E16: Serious | F16: MV SuperFerry 12 | H16: Ferry | I16: Philippines | K16: PH-RORO-8455 | L16: 7180 | M16: 116.1 | N16: 18.2 | O16: Twin diesel propulsion | P16: 6180 | Q16: ClassNK | R16: 2010 | S16: 10.207 | T16: 123.955 | U16: Cebu | V16: Cebu | W16: Cebu Strait | X16: Cebu-Mactan Southern Approach | Y16: 1.4 | Z16: 4 | AA16: Moderate | AB16: National RoRo Services | AC16: +63 32 414 9200 | AD16: National RoRo Services | AE16: Cebu Domestic Port, Cebu, Philippines | AF16: Cebu | AG16: Ormoc | AH16: Cebu Strait domestic passenger corridor | AI16: Passengers | AJ16: 145 passengers and mixed rolling cargo | AK16: PCG | AL16: Mobile App | AM16: Under Review | AN16: Ferry struck a fixed mooring dolphin while approaching Cebu under a crowded berthing sequence. | AO16: 09:28 inbound queue formed; 09:35 astern movement delayed; 09:40 starboard quarter contact with dolphin. | AP16: Terminal response teams assisted in mooring while the crew checked passenger areas and vehicle deck securing. | AQ16: Communication Failure | AR16: Navigation Error | AS16: The final approach speed remained high for the available berth spacing and tug support was delayed. | AT16: Hull Damage | Third-Party Property | AU16: 18 | AV16: 145 | AW16: 0 | AX16: 5 | AY16: Review final-approach speed limits and berth sequencing controls for Cebu domestic ferry terminals. | AZ16: Berth CCTV | Port VTS Log | Damage Assessment
A17: INC-2025-000295 | B17: 45837.592 | C17: Flooding | D17: Injury | E17: Serious | F17: MV Island Hopper | H17: Ferry | I17: Philippines | K17: PH-RORO-2024 | L17: 3960 | M17: 74.6 | N17: 14.1 | O17: Twin diesel propulsion | P17: 3210 | Q17: RINA | R17: 2014 | S17: 9.769 | T17: 124.031 | U17: Tagbilaran | V17: Bohol | W17: Bohol Sea | X17: Cebu-Bohol Passenger Corridor | Y17: 1.7 | Z17: 5 | AA17: Moderate | AB17: Archipelago Transport Link | AC17: +63 43 288 5221 | AD17: Archipelago Transport Link | AE17: Calapan Port Complex, Oriental Mindoro, Philippines | AF17: Cebu | AG17: Tagbilaran | AH17: Cebu-Tagbilaran inter-island service lane | AI17: Passengers | AJ17: 82 passengers and 18 light vehicles | AK17: PCG | AL17: Email Intake | AM17: Verified | AN17: RoRo ferry developed flooding in a vehicle deck compartment during a Bohol Sea crossing. | AO17: 13:55 spray ingress noticed; 14:04 compartment alarm; 14:12 dewatering and speed reduction initiated. | AP17: Crew closed deck openings, shifted vehicles, and stabilized the vessel before proceeding under escort. | AQ17: Violation of Procedures | AR17: Mechanical Failure | AS17: A degraded deck drain and unsecured ramp seal allowed water to accumulate during head seas. | AT17: Equipment Damage | AU17: 12 | AV17: 82 | AW17: 0 | AX17: 1 | AY17: Increase ramp and drain inspection frequency on Bohol Sea RoRo services during monsoon periods. | AZ17: Ramp Seal Inspection | Vehicle Deck Photos | Escort Clearance
A18: INC-2025-000317 | B18: 45852.962 | C18: Collision | D18: Injury | E18: Serious | F18: MT Southern Crest | H18: Oil Tanker | I18: Singapore | J18: IMO 9612259 | K18: SG-TK-5517 | L18: 23110 | M18: 174.2 | N18: 28.6 | O18: Slow-speed marine diesel | P18: 9340 | Q18: Lloyd's Register | R18: 2012 | S18: 10.989 | T18: 125.543 | U18: Liloan | V18: Southern Leyte | W18: Surigao Strait | X18: Liloan-Surigao Crossing | Y18: 2.2 | Z18: 6 | AA18: Poor | AB18: Southern Crest Tankers | AC18: +65 6883 5500 | AD18: Crest Offshore Management | AE18: Anson Road, Singapore | AF18: Liloan | AG18: Surigao | AH18: Southern Leyte-Surigao strait crossing lane | AI18: Fuel / Oil | AJ18: 18,000 barrels bunker fuel | AK18: MARINA | AL18: Inter-agency Intake | AM18: Published | AN18: Tanker made glancing contact with a coastal cargo vessel in rain clutter inside Surigao Strait. | AO18: 22:48 rain cell entered radar arc; 22:59 crossing target confusion reported; 23:05 contact occurred. | AP18: Master reduced speed, separated from traffic, and completed pollution prevention checks before proceeding. | AQ18: Communication Failure | Fatigue | AR18: Navigation Error | AS18: Radar interpretation degraded in heavy rain and voice coordination between bridges was incomplete. | AT18: Hull Damage | AU18: 26 | AV18: 0 | AW18: 0 | AX18: 2 | AY18: Issue rain-clutter bridge guidance and bridge manning reinforcement requirements for Surigao Strait transits. | AZ18: Radar Screenshot | VHF Transcript | Pollution Prevention Check
A19: INC-2025-000336 | B19: 45869.262 | C19: Pollution Incident | D19: Pollution | E19: Serious | F19: MT Ocean Star | H19: Oil Tanker | I19: Singapore | J19: IMO 9338894 | K19: SG-TK-4218 | L19: 29400 | M19: 183.8 | N19: 32 | O19: Slow-speed marine diesel | P19: 9780 | Q19: Lloyd's Register | R19: 2008 | S19: 9.654 | T19: 118.535 | U19: Puerto Princesa | V19: Palawan | W19: Palawan Approaches | X19: Puerto Princesa Western Approach | Y19: 1.6 | Z19: 4 | AA19: Good | AB19: Blue Meridian Tankers | AC19: +65 6712 9088 | AD19: Meridian Offshore Management | AE19: Jurong Port Road, Singapore | AF19: Cuyo | AG19: Puerto Princesa | AH19: West Palawan coastal approach lane | AI19: Fuel / Oil | AJ19: 22,500 barrels marine diesel | AK19: MARINA | AL19: Web Portal | AM19: Published | AN19: Minor sheen was observed astern of the tanker while inbound to Puerto Princesa anchorage. | AO19: 06:03 sheen first reported; 06:11 deck inspection started; 06:18 transfer line leak identified and isolated. | AP19: Crew suspended transfer preparations, deployed absorbent boom, and coordinated with the port response team. | AQ19: Inadequate Training | AR19: Mechanical Failure | AS19: A loose transfer line coupling allowed residual product to escape during pre-berthing checks. | AT19: Environmental Impact | AU19: 28 | AV19: 0 | AW19: 0 | AX19: 0 | AY19: Mandate tighter pre-berthing hose and coupling checks for tankers entering Palawan anchorages. | AZ19: Sheen Photo Log | Port Response Report | Transfer Line Inspection
A20: INC-2025-000352 | B20: 45884.114 | C20: Machinery Failure | D20: None | E20: Less Serious | F20: MV Eastern Mariner | H20: Container Ship | I20: Liberia | J20: IMO 9384451 | K20: LR-CS-6921 | L20: 20310 | M20: 176.7 | N20: 28.1 | O20: Diesel engine | P20: 10620 | Q20: DNV | R20: 2011 | S20: 6.871 | T20: 125.757 | U20: Davao | V20: Davao del Sur | W20: Davao Gulf | X20: Samal-Davao Pilotage Route | Y20: 1 | Z20: 3 | AA20: Good | AB20: Eastern Gateway Shipping | AC20: +231 770 552118 | AD20: Gateway Marine Management | AE20: Monrovia Registry Office | AF20: General Santos | AG20: Davao | AH20: Davao Gulf northbound merchant lane | AI20: Containers | AJ20: 1,480 TEU mixed retail cargo | AK20: MARINA | AL20: Web Portal | AM20: Verified | AN20: Container ship experienced steering gear lag while aligning for pilot boarding inside Davao Gulf. | AO20: 02:36 response lag noticed; 02:40 manual steering engaged; 02:44 redundancy checks completed. | AP20: Bridge and engine teams shifted to standby steering mode and postponed pilot boarding until tests were complete. | AQ20: Inadequate Training | AR20: Mechanical Failure | AS20: Hydraulic pressure fluctuation inside the steering gear control loop caused delayed helm response. | AT20: Equipment Damage | AU20: 23 | AV20: 0 | AW20: 0 | AX20: 0 | AY20: Require steering gear redundancy checks before pilot boarding in constrained gulf approaches. | AZ20: Steering Gear Alarm Printout | Pilot Delay Notice | Engineering Test Sheet
A21: INC-2025-000371 | B21: 45904.786 | C21: Swamping | D21: Fatality | E21: Very Serious | F21: MV Strait Guardian | H21: General Cargo | I21: Philippines | K21: PH-GC-9194 | L21: 4210 | M21: 86.5 | N21: 14.9 | O21: Marine diesel | P21: 3940 | Q21: Bureau Veritas | R21: 2008 | S21: 12.746 | T21: 124.402 | U21: Matnog | V21: Sorsogon | W21: San Bernardino Strait | X21: Matnog-Allen Ferry Transit | Y21: 3.6 | Z21: 8 | AA21: Poor | AB21: Strait Guardian Shipping | AC21: +63 56 851 3910 | AD21: Guardian Coastal Freight | AE21: Allen Port, Northern Samar, Philippines | AF21: Matnog | AG21: Allen | AH21: San Bernardino inter-island ferry route | AI21: General Cargo | AJ21: 4,200 MT aggregates and construction equipment | AK21: PCG | AL21: Manual Encoding | AM21: Published | AN21: General cargo vessel was overwhelmed by repeated green water over the bow and lost stability in San Bernardino Strait. | AO21: 18:33 heavy weather warning repeated; 18:47 forward deck flooding; 18:52 loss of stability and partial abandonment. | AP21: Crew attempted to secure deck cargo and dewater holds before distress traffic was transmitted. | AQ21: Violation of Procedures | Communication Failure | AR21: Weather Conditions | AS21: Improper deck cargo securing and a late decision to seek shelter left the vessel exposed to heavy seas. | AT21: Hull Damage | Cargo Damage | AU21: 17 | AV21: 0 | AW21: 1 | AX21: 4 | AY21: Issue deck cargo securing advisories and enforce weather rerouting for small cargo vessels in San Bernardino Strait. | AZ21: Cargo Securing Photos | Weather Bulletin | Distress Log
A22: INC-2025-000389 | B22: 45922.465 | C22: Collision | D22: Property Damage | E22: Serious | F22: MV Pacific Dream | H22: Bulk Carrier | I22: Marshall Islands | J22: IMO 9440878 | K22: MH-BC-3019 | L22: 27850 | M22: 190.4 | N22: 32.1 | O22: Slow-speed diesel engine | P22: 11860 | Q22: ABS | R22: 2007 | S22: 8.512 | T22: 124.747 | U22: Cagayan de Oro | V22: Misamis Oriental | W22: Macajalar Bay | X22: Macajalar Bay Bulk Access Lane | Y22: 0.8 | Z22: 2 | AA22: Good | AB22: TransPacific Dry Bulk | AC22: +692 625 9911 | AD22: TransPacific Marine Services | AE22: Majuro Registry Office | AF22: Iligan | AG22: Cagayan de Oro | AH22: Macajalar Bay industrial shipping lane | AI22: Bulk cargo | AJ22: 20,500 MT clinker and steel billets | AK22: MARINA | AL22: Inter-agency Intake | AM22: Published | AN22: Bulk carrier contacted a berth fender line and nearby service craft while shifting inside Macajalar Bay. | AO22: 10:58 berth shift commenced; 11:05 astern propulsion delayed; 11:10 contact with service craft. | AP22: Bridge team stopped the shift, checked for pollution risk, and resumed only after harbor master clearance. | AQ22: Communication Failure | AR22: Navigation Error | AS22: Conflicting tug and berth instructions caused a late correction during low-speed maneuvering. | AT22: Third-Party Property | Hull Damage | AU22: 24 | AV22: 0 | AW22: 0 | AX22: 1 | AY22: Standardize tug-master-harbor communication procedures during industrial berth shifts in Macajalar Bay. | AZ22: Harbor Master Note | Shift Plan | Service Craft Damage Report
A23: INC-2025-000406 | B23: 45939.936 | C23: Collision | D23: Property Damage | E23: Less Serious | F23: MV Verde Logistics | H23: General Cargo | I23: Philippines | K23: PH-GC-8344 | L23: 5120 | M23: 91.2 | N23: 15.4 | O23: Marine diesel | P23: 4460 | Q23: ClassNK | R23: 2015 | S23: 10.684 | T23: 122.599 | U23: Iloilo | V23: Iloilo | W23: Iloilo Strait | X23: Iloilo-Guimaras Transit Lane | Y23: 1.1 | Z23: 3 | AA23: Moderate | AB23: Verde Coastal Logistics | AC23: +63 43 723 1180 | AD23: Verde Coastal Logistics | AE23: Batangas Port, Batangas, Philippines | AF23: Iloilo | AG23: Bacolod | AH23: Panay-Negros coastal ferry lane | AI23: General Cargo | AJ23: 5,100 MT bagged feed and construction supplies | AK23: PCG | AL23: Web Portal | AM23: Verified | AN23: General cargo vessel allided with a navigation buoy while crossing Iloilo Strait at night. | AO23: 22:17 outbound lane entered; 22:24 buoy light confusion reported; 22:28 allision recorded. | AP23: Crew corrected track immediately and checked forepeak spaces before completing transit at reduced speed. | AQ23: Fatigue | AR23: Navigation Error | AS23: A fatigued watch team misidentified buoy characteristics and stood too close to the channel edge. | AT23: Hull Damage | Third-Party Property | AU23: 16 | AV23: 0 | AW23: 0 | AX23: 1 | AY23: Review night navigation watch rotations and channel-mark identification guidance for Iloilo Strait transits. | AZ23: Buoy Maintenance Photo | Watch Schedule | Track Plot
A24: INC-2025-000422 | B24: 45957.566 | C24: Collision | D24: Fatality | E24: Very Serious | F24: MV Pacific Trader | G24: MV Eastern Star | H24: Bulk Carrier | I24: Philippines | J24: IMO 9482713 | K24: PH-2026-7781 | L24: 25000 | M24: 189.6 | N24: 32.2 | O24: Diesel engine | P24: 11200 | Q24: Bureau Veritas | R24: 2006 | S24: 14.633 | T24: 120.811 | U24: Manila | V24: Metro Manila | W24: Manila Bay | X24: Manila Bay North Approach | Y24: 1.5 | Z24: 4 | AA24: Poor | AB24: Pacific Shipping Lines | AC24: +63 2 8123 4567 | AD24: Pacific Marine Operations | AE24: Port Area, Manila, Philippines | AF24: Subic | AG24: Manila | AH24: Subic-Manila inbound traffic lane | AI24: Bulk cargo | AJ24: 18,000 MT cement clinker | AK24: MARINA | AL24: Inter-agency Intake | AM24: Published | AN24: Bulk carrier collided with a fishing vessel at the edge of the Manila Bay north approach under patchy visibility. | AO24: 13:18 visibility reduced; 13:29 small target lost in clutter; 13:35 collision with fishing vessel. | AP24: Rescue boats were deployed immediately while the master stabilized the vessel and informed VTS. | AQ24: Communication Failure | Violation of Procedures | AR24: Navigation Error | AS24: Inadequate lookout reinforcement during poor visibility led to late detection of the fishing vessel crossing ahead. | AT24: Hull Damage | Third-Party Property | AU24: 22 | AV24: 0 | AW24: 2 | AX24: 6 | AY24: Require heightened lookout manning and fishing-vessel crossing advisories in Manila Bay during reduced visibility. | AZ24: VTS Playback | Rescue Summary | Fishing Vessel Statement
A25: INC-2025-000441 | B25: 45974.738 | C25: Fire/Explosion | D25: Fatality | E25: Very Serious | F25: MT Southern Crest | H25: Oil Tanker | I25: Singapore | J25: IMO 9612259 | K25: SG-TK-5517 | L25: 23110 | M25: 174.2 | N25: 28.6 | O25: Slow-speed marine diesel | P25: 9340 | Q25: Lloyd's Register | R25: 2012 | S25: 13.779 | T25: 121.083 | U25: Batangas | V25: Batangas | W25: Verde Island Passage | X25: Batangas-Calapan Transit Lane | Y25: 1.8 | Z25: 5 | AA25: Moderate | AB25: Southern Crest Tankers | AC25: +65 6883 5500 | AD25: Crest Offshore Management | AE25: Anson Road, Singapore | AF25: Batangas | AG25: Calapan | AH25: Verde Island Passage east-west corridor | AI25: Fuel / Oil | AJ25: 18,000 barrels bunker fuel | AK25: MARINA | AL25: Manual Encoding | AM25: Published | AN25: Pump room explosion injured multiple crew while the tanker transited a busy section of the Verde Island Passage. | AO25: 17:33 gas readings abnormal; 17:38 transfer line investigation; 17:42 flash explosion and compartment isolation. | AP25: Damage control teams sealed the space, treated casualties, and diverted the vessel clear of dense traffic. | AQ25: Inadequate Training | Violation of Procedures | AR25: Mechanical Failure | AS25: Vapor accumulation in the pump room ignited after a maintenance bypass left unsafe conditions uncorrected. | AT25: Equipment Damage | Hull Damage | AU25: 26 | AV25: 0 | AW25: 1 | AX25: 8 | AY25: Strengthen enclosed-space gas monitoring and maintenance authorization controls for tankers in high-traffic corridors. | AZ25: Gas Meter Log | Pump Room Inspection | Medical Evacuation Record
A26: INC-2025-000458 | B26: 45989.207 | C26: Collision | D26: None | E26: Near Miss | F26: MV Island Express | H26: Ferry | I26: Philippines | J26: IMO 9134452 | K26: OFN-55281 | L26: 8450 | M26: 118.4 | N26: 18.3 | O26: Twin diesel propulsion | P26: 6400 | Q26: Nippon Kaiji Kyokai | R26: 2011 | S26: 10.238 | T26: 123.951 | U26: Cebu | V26: Cebu | W26: Cebu Strait | X26: Cebu-Mactan Southern Approach | Y26: 1 | Z26: 3 | AA26: Good | AB26: Island Ferry Holdings | AC26: +63 32 455 1188 | AD26: Island Express Ferries | AE26: Pier 3, Cebu City, Philippines | AF26: Cebu | AG26: Ormoc | AH26: Cebu Strait domestic passenger corridor | AI26: Passengers | AJ26: 187 passengers with accompanied baggage | AK26: PCG | AL26: Mobile App | AM26: Under Review | AN26: Passenger ferry reported a near-miss crossing event with an outbound coaster near the Mactan approach. | AO26: 04:49 coaster acquired; 04:55 CPA reduced rapidly; 04:58 avoiding action passed clear with no contact. | AP26: Master filed a near-miss report on arrival and requested review of crossing traffic sequencing. | AQ26: Communication Failure | AR26: Navigation Error | AS26: Neither bridge established timely passing intentions despite converging tracks near a terminal approach. | AT26: None Reported | AU26: 15 | AV26: 187 | AW26: 0 | AX26: 0 | AY26: Use near-miss reporting to refine crossing management and VHF discipline in Cebu Strait. | AZ26: Near-Miss Report | AIS Replay | Bridge Watch Statement
A27: INC-2025-000476 | B27: 46007.386 | C27: Capsizing | D27: Fatality | E27: Serious | F27: FB Dona Pilar | H27: Fishing Vessel | I27: Philippines | K27: PH-FV-2201 | L27: 94 | M27: 25.7 | N27: 6.5 | O27: Marine diesel | P27: 470 | R27: 2005 | S27: 10.955 | T27: 125.552 | U27: Liloan | V27: Southern Leyte | W27: Surigao Strait | X27: Liloan-Surigao Crossing | Y27: 2.9 | Z27: 7 | AA27: Moderate | AB27: Pilar Deep Sea Ventures | AC27: +63 53 834 4482 | AD27: Pilar Deep Sea Ventures | AE27: Surigao Fishing Port, Surigao City, Philippines | AF27: Liloan | AG27: Surigao | AH27: Southern Leyte-Surigao strait crossing lane | AI27: Fish Catch | AJ27: 8 MT pelagic catch and fishing gear | AK27: PCG | AL27: Manual Encoding | AM27: Published | AN27: Small fishing vessel capsized after hauling a heavy catch close to the Surigao crossing lane. | AO27: 08:58 gear hauling started; 09:11 heel increased rapidly; 09:16 capsize and rescue by nearby banca. | AP27: Survivors clung to overturned hull until they were recovered by companion fishing craft. | AQ27: Violation of Procedures | AR27: Weather Conditions | AS27: Combined weight shift and quartering seas reduced stability below safe limits during hauling. | AT27: Hull Damage | Cargo Damage | AU27: 9 | AV27: 0 | AW27: 1 | AX27: 2 | AY27: Promote safe hauling envelopes and weather-go/no-go guidance for small fishing craft near Surigao Strait. | AZ27: Catch Log | Survivor Interview | Rescue Boat Track
A28: INC-2026-000021 | B28: 46030.606 | C28: Collision | D28: Injury | E28: Serious | F28: FB Santa Rosa | H28: Fishing Vessel | I28: Philippines | K28: PH-FV-11892 | L28: 110 | M28: 28.4 | N28: 6.9 | O28: Marine diesel | P28: 540 | R28: 2002 | S28: 9.682 | T28: 118.486 | U28: Puerto Princesa | V28: Palawan | W28: Palawan Approaches | X28: Puerto Princesa Western Approach | Y28: 1.7 | Z28: 5 | AA28: Moderate | AB28: Santa Rosa Fishing Cooperative | AC28: +63 78 889 2121 | AD28: Santa Rosa Fishing Cooperative | AE28: Aparri Fishing Port, Cagayan, Philippines | AF28: Cuyo | AG28: Puerto Princesa | AH28: West Palawan coastal approach lane | AI28: Fish Catch | AJ28: 12 MT mixed pelagic catch | AK28: PCG | AL28: Email Intake | AM28: Verified | AN28: Fishing vessel collided with a fast coastal passenger craft near the Puerto Princesa western approach. | AO28: 14:20 crossing target sighted; 14:29 horn signal exchanged late; 14:32 contact on fishing vessel stern quarter. | AP28: Passenger craft recovered injured fishermen and escorted the damaged vessel toward sheltered water. | AQ28: Communication Failure | Fatigue | AR28: Human Error | AS28: Both craft relied on visual passing assumptions without clear early communication of intentions. | AT28: Hull Damage | AU28: 10 | AV28: 0 | AW28: 0 | AX28: 2 | AY28: Increase small-craft and passenger-craft separation guidance in Puerto Princesa approaches. | AZ28: Damage Photos | Passenger Craft Statement | Rescue Coordination Log
A29: INC-2026-000044 | B29: 46046.098 | C29: Grounding | D29: None | E29: Less Serious | F29: MV Cargo Link | H29: Container Ship | I29: Panama | J29: IMO 9291173 | K29: PA-CS-4421 | L29: 18600 | M29: 172.3 | N29: 27.9 | O29: Diesel engine | P29: 10240 | Q29: DNV | R29: 2010 | S29: 6.846 | T29: 125.721 | U29: Davao | V29: Davao del Sur | W29: Davao Gulf | X29: Samal-Davao Pilotage Route | Y29: 1.2 | Z29: 3 | AA29: Good | AB29: Cargo Link Asia Ltd. | AC29: +507 206 8100 | AD29: Cargo Link Shipmanagement | AE29: Panama City, Panama | AF29: General Santos | AG29: Davao | AH29: Davao Gulf northbound merchant lane | AI29: Containers | AJ29: 1,240 TEU mixed consumer cargo | AK29: MARINA | AL29: Web Portal | AM29: Verified | AN29: Container ship brushed soft bottom while aligning with the pilot boarding lane in Davao Gulf. | AO29: 02:13 pilot boarding delayed; 02:19 drift developed; 02:21 soft grounding and immediate engine stop. | AP29: Vessel refloated on the next tide after draft checks confirmed no progressive damage. | AQ29: Violation of Procedures | AR29: Navigation Error | AS29: The vessel remained too close to the shallow lane edge while waiting for pilot instructions. | AT29: Hull Damage | AU29: 20 | AV29: 0 | AW29: 0 | AX29: 0 | AY29: Refine waiting area guidance and pilot boarding tracks for deep-draft arrivals in Davao Gulf. | AZ29: Draft Survey | Pilot Boarding Record | Track Plot
A30: INC-2026-000062 | B30: 46064.825 | C30: Machinery Failure | D30: Injury | E30: Serious | F30: MV Samar Venture | H30: Ferry | I30: Philippines | K30: PH-RORO-5612 | L30: 5120 | M30: 92.2 | N30: 16.7 | O30: Twin screw diesel | P30: 4680 | Q30: Bureau Veritas | R30: 2013 | S30: 12.79 | T30: 124.377 | U30: Matnog | V30: Sorsogon | W30: San Bernardino Strait | X30: Matnog-Allen Ferry Transit | Y30: 2.4 | Z30: 6 | AA30: Moderate | AB30: Eastern Nautical Transport | AC30: +63 56 812 9951 | AD30: Samar Venture Ferries | AE30: Matnog Ferry Terminal, Sorsogon, Philippines | AF30: Matnog | AG30: Allen | AH30: San Bernardino inter-island ferry route | AI30: Passengers | AJ30: 132 passengers and 28 rolling vehicles | AK30: PCG | AL30: Mobile App | AM30: Under Review | AN30: RoRo ferry lost one propulsion line while transiting the central San Bernardino Strait lane. | AO30: 19:37 abnormal vibration noted; 19:44 shaft protection trip; 19:48 reduced maneuverability declared. | AP30: Crew secured passengers, deployed standby anchors, and received escort from a coast guard patrol craft. | AQ30: Inadequate Training | AR30: Mechanical Failure | AS30: A bearing lubrication fault caused rapid overheating and forced shutdown of one propulsion train. | AT30: Equipment Damage | AU30: 18 | AV30: 132 | AW30: 0 | AX30: 3 | AY30: Review propulsion redundancy procedures and escort readiness for San Bernardino ferry services. | AZ30: Propulsion Alarm Log | Escort Dispatch Sheet | Passenger Advisory
A31: INC-2026-000083 | B31: 46080.248 | C31: Fire/Explosion | D31: Fatality | E31: Very Serious | F31: MT Southern Crest | H31: Oil Tanker | I31: Singapore | J31: IMO 9612259 | K31: SG-TK-5517 | L31: 23110 | M31: 174.2 | N31: 28.6 | O31: Slow-speed marine diesel | P31: 9340 | Q31: Lloyd's Register | R31: 2012 | S31: 8.552 | T31: 124.768 | U31: Cagayan de Oro | V31: Misamis Oriental | W31: Macajalar Bay | X31: Macajalar Bay Bulk Access Lane | Y31: 0.9 | Z31: 2 | AA31: Good | AB31: Southern Crest Tankers | AC31: +65 6883 5500 | AD31: Crest Offshore Management | AE31: Anson Road, Singapore | AF31: Iligan | AG31: Cagayan de Oro | AH31: Macajalar Bay industrial shipping lane | AI31: Fuel / Oil | AJ31: 18,000 barrels bunker fuel | AK31: MARINA | AL31: Inter-agency Intake | AM31: Published | AN31: Cargo pump motor fire escalated during pre-discharge checks at the outer Macajalar Bay anchorage. | AO31: 05:43 electrical fault warning; 05:52 smoke observed; 05:57 localized fire and emergency shutdown. | AP31: Fire team deployed breathing apparatus, isolated electrical feeds, and prevented escalation to cargo spaces. | AQ31: Inadequate Training | AR31: Mechanical Failure | AS31: Poor cable insulation and delayed isolation of the faulty motor allowed a localized fire to intensify. | AT31: Equipment Damage | AU31: 26 | AV31: 0 | AW31: 1 | AX31: 5 | AY31: Tighten electrical integrity inspections for tankers preparing for discharge at industrial anchorages. | AZ31: Motor Inspection Report | Fire Boundary Cooling Log | Anchorage Safety Notice
A32: INC-2026-000101 | B32: 46091.278 | C32: Collision | D32: Fatality | E32: Very Serious | F32: MV Pacific Trader | G32: MV Eastern Star | H32: Bulk Carrier | I32: Philippines | J32: IMO 9482713 | K32: PH-2026-7781 | L32: 25000 | M32: 189.6 | N32: 32.2 | O32: Diesel engine | P32: 11200 | Q32: Bureau Veritas | R32: 2006 | S32: 14.405 | T32: 120.839 | U32: Manila | V32: Metro Manila | W32: Manila Bay | X32: Manila Bay South Approach | Y32: 2.1 | Z32: 6 | AA32: Poor | AB32: Pacific Shipping Lines | AC32: +63 2 8123 4567 | AD32: Pacific Marine Operations | AE32: Port Area, Manila, Philippines | AF32: Batangas | AG32: Manila | AH32: Batangas-Manila gateway lane | AI32: Bulk cargo | AJ32: 18,000 MT cement clinker | AK32: MARINA | AL32: Inter-agency Intake | AM32: Under Review | AN32: Bulk carrier struck a wooden fishing vessel south of Corregidor while inbound through the Manila Bay gateway. | AO32: 06:22 low visibility advisory; 06:34 radar target correlation failed; 06:40 collision and immediate rescue operations. | AP32: Crew launched rescue boats, reported the casualty to VTS, and suspended the approach to preserve the incident scene. | AQ32: Communication Failure | Violation of Procedures | AR32: Navigation Error | AS32: Reduced visibility, incomplete small-target detection, and late speed reduction materially contributed to the collision. | AT32: Hull Damage | Third-Party Property | AU32: 22 | AV32: 0 | AW32: 3 | AX32: 7 | AY32: Introduce fishing-vessel density advisories and stricter reduced-visibility transit controls for Manila Bay approaches. | AZ32: Scene Photos | AIS Playback | Rescue Timeline
A33: INC-2026-000118 | B33: 46104.631 | C33: Person Overboard | D33: Fatality | E33: Serious | F33: MV SuperFerry 12 | H33: Ferry | I33: Philippines | K33: PH-RORO-8455 | L33: 7180 | M33: 116.1 | N33: 18.2 | O33: Twin diesel propulsion | P33: 6180 | Q33: ClassNK | R33: 2010 | S33: 9.803 | T33: 124.003 | U33: Tagbilaran | V33: Bohol | W33: Bohol Sea | X33: Cebu-Bohol Passenger Corridor | Y33: 1.8 | Z33: 5 | AA33: Moderate | AB33: National RoRo Services | AC33: +63 32 414 9200 | AD33: National RoRo Services | AE33: Cebu Domestic Port, Cebu, Philippines | AF33: Cebu | AG33: Tagbilaran | AH33: Cebu-Tagbilaran inter-island service lane | AI33: Passengers | AJ33: 145 passengers and mixed rolling cargo | AK33: PCG | AL33: Mobile App | AM33: Published | AN33: Passenger went overboard during afternoon transit between Cebu and Tagbilaran. | AO33: 14:56 seat check raised concern; 15:02 deck search started; 15:08 man overboard maneuver initiated. | AP33: Crew deployed rings, plotted drift, and coordinated nearby merchant traffic to widen the search box. | AQ33: Fatigue | AR33: Human Error | AS33: Delayed detection and insufficient control of open deck areas prolonged the response timeline. | AT33: None Reported | AU33: 18 | AV33: 145 | AW33: 1 | AX33: 0 | AY33: Increase deck patrol frequency and passenger safety messaging on open-deck ferry routes in the Bohol Sea. | AZ33: Muster Checklist | Drift Calculation | Passenger Interview Notes
A34: INC-2026-000134 | B34: 46117.313 | C34: Flooding | D34: None | E34: Less Serious | F34: MV Island Hopper | H34: Ferry | I34: Philippines | K34: PH-RORO-2024 | L34: 3960 | M34: 74.6 | N34: 14.1 | O34: Twin diesel propulsion | P34: 3210 | Q34: RINA | R34: 2014 | S34: 10.658 | T34: 122.57 | U34: Iloilo | V34: Iloilo | W34: Iloilo Strait | X34: Iloilo-Guimaras Transit Lane | Y34: 1.2 | Z34: 4 | AA34: Good | AB34: Archipelago Transport Link | AC34: +63 43 288 5221 | AD34: Archipelago Transport Link | AE34: Calapan Port Complex, Oriental Mindoro, Philippines | AF34: Iloilo | AG34: Bacolod | AH34: Panay-Negros coastal ferry lane | AI34: Passengers | AJ34: 82 passengers and 18 light vehicles | AK34: PCG | AL34: Email Intake | AM34: Verified | AN34: Repeat flooding event was recorded on a RoRo ferry during another short-haul Iloilo Strait service. | AO34: 07:20 spray ingress noted; 07:27 compartment rechecked; 07:31 pumps contained the ingress rate. | AP34: Crew returned to Iloilo for inspection before resuming service later in the day with reduced vehicle loading. | AQ34: Inadequate Training | AR34: Mechanical Failure | AS34: Deferred maintenance on a recurring seal issue allowed the defect to reappear under routine service conditions. | AT34: Equipment Damage | AU34: 12 | AV34: 82 | AW34: 0 | AX34: 0 | AY34: Use repeat-defect tracking to suspend vessels from service until recurring flooding defects are fully corrected. | AZ34: Repeat Defect Log | Repair Order | Service Suspension Note
A35: INC-2026-000149 | B35: 46131.999 | C35: Grounding | D35: Injury | E35: Serious | F35: MV Verde Logistics | H35: General Cargo | I35: Philippines | K35: PH-GC-8344 | L35: 5120 | M35: 91.2 | N35: 15.4 | O35: Marine diesel | P35: 4460 | Q35: ClassNK | R35: 2015 | S35: 13.752 | T35: 121.078 | U35: Batangas | V35: Batangas | W35: Verde Island Passage | X35: Batangas-Calapan Transit Lane | Y35: 1.6 | Z35: 4 | AA35: Moderate | AB35: Verde Coastal Logistics | AC35: +63 43 723 1180 | AD35: Verde Coastal Logistics | AE35: Batangas Port, Batangas, Philippines | AF35: Batangas | AG35: Calapan | AH35: Verde Island Passage east-west corridor | AI35: General Cargo | AJ35: 5,100 MT bagged feed and construction supplies | AK35: PCG | AL35: Web Portal | AM35: Under Review | AN35: General cargo vessel grounded again near the eastern Verde Passage after a night transit route deviation. | AO35: 23:41 route amendment requested; 23:52 shallow-water alarm; 23:58 grounding and engine stop. | AP35: Bridge team initiated soundings, contacted nearby traffic, and waited for daylight salvage assessment. | AQ35: Violation of Procedures | Fatigue | AR35: Navigation Error | AS35: The bridge team bypassed a route cross-check and relied on visual shoreline cues during night transit. | AT35: Hull Damage | AU35: 16 | AV35: 0 | AW35: 0 | AX35: 2 | AY35: Flag repeat grounding patterns in the Verde Passage and prioritize night-navigation compliance inspections. | AZ35: Night Track Replay | Sounding Log | Salvage Assessment
A36: INC-2026-000164 | B36: 46144.489 | C36: Capsizing | D36: Fatality | E36: Very Serious | F36: FB San Miguel | H36: Fishing Vessel | I36: Philippines | K36: PH-FV-8743 | L36: 82 | M36: 24.1 | N36: 6.2 | O36: Marine diesel | P36: 430 | R36: 2004 | S36: 6.85 | T36: 125.76 | U36: Davao | V36: Davao del Sur | W36: Davao Gulf | X36: Samal-Davao Pilotage Route | Y36: 3.4 | Z36: 8 | AA36: Poor | AB36: San Miguel Fisheries | AC36: +63 82 225 9167 | AD36: San Miguel Fisheries | AE36: Davao Fish Port, Davao City, Philippines | AF36: General Santos | AG36: Davao | AH36: Davao Gulf northbound merchant lane | AI36: Fish Catch | AJ36: 7 MT tuna and mixed catch | AK36: PCG | AL36: Manual Encoding | AM36: Published | AN36: Fishing vessel capsized during squall conditions near the eastern edge of the Davao Gulf pilotage route. | AO36: 11:28 squall line entered gulf; 11:39 heavy heel reported; 11:44 capsize and distress call lost. | AP36: Companion vessels commenced local search before formal SAR units arrived from Davao. | AQ36: Violation of Procedures | AR36: Weather Conditions | AS36: The vessel remained underway in a fast-moving squall despite available shelter inside the gulf. | AT36: Total Loss | AU36: 8 | AV36: 0 | AW36: 3 | AX36: 0 | AY36: Strengthen squall-warning dissemination and sheltering procedures for small craft inside Davao Gulf. | AZ36: Squall Advisory | SAR Log | Survivor Debrief
A37: INC-2026-000183 | B37: 46160.15 | C37: Collision | D37: Injury | E37: Serious | F37: MV Visayan Princess | H37: Passenger Vessel | I37: Philippines | J37: IMO 9006173 | K37: PH-PAX-4412 | L37: 6720 | M37: 109.3 | N37: 17.6 | O37: Dual diesel propulsion | P37: 5810 | Q37: RINA | R37: 2009 | S37: 10.199 | T37: 123.929 | U37: Cebu | V37: Cebu | W37: Cebu Strait | X37: Cebu-Mactan Southern Approach | Y37: 1.5 | Z37: 4 | AA37: Moderate | AB37: Visayan Coastal Lines | AC37: +63 32 332 7777 | AD37: Visayan Passenger Shipping | AE37: North Reclamation Area, Cebu City, Philippines | AF37: Cebu | AG37: Ormoc | AH37: Cebu Strait domestic passenger corridor | AI37: Passengers | AJ37: 126 passengers and light vehicle deck cargo | AK37: PCG | AL37: Inter-agency Intake | AM37: Published | AN37: Passenger vessel struck a small inter-island cargo craft while overtaking south of Mactan. | AO37: 03:24 overtaking initiated; 03:31 cargo craft altered slightly; 03:36 side contact and stoppage. | AP37: Both vessels separated safely and the passenger vessel rendered assistance before resuming escorted transit. | AQ37: Communication Failure | AR37: Navigation Error | AS37: Late overtaking communication and insufficient passing distance led to side contact in confined water. | AT37: Hull Damage | Third-Party Property | AU37: 16 | AV37: 126 | AW37: 0 | AX37: 4 | AY37: Review overtaking practices and mandatory reporting points for mixed traffic in Cebu Strait. | AZ37: Overtaking Report | Port Control Recording | Damage Survey
A38: INC-2026-000207 | B38: 46174.84 | C38: Machinery Failure | D38: None | E38: Less Serious | F38: MV Cargo Link | H38: Container Ship | I38: Panama | J38: IMO 9291173 | K38: PA-CS-4421 | L38: 18600 | M38: 172.3 | N38: 27.9 | O38: Diesel engine | P38: 10240 | Q38: DNV | R38: 2010 | S38: 14.666 | T38: 120.802 | U38: Manila | V38: Metro Manila | W38: Manila Bay | X38: Manila Bay North Approach | Y38: 1.2 | Z38: 3 | AA38: Good | AB38: Cargo Link Asia Ltd. | AC38: +507 206 8100 | AD38: Cargo Link Shipmanagement | AE38: Panama City, Panama | AF38: Subic | AG38: Manila | AH38: Subic-Manila inbound traffic lane | AI38: Containers | AJ38: 1,240 TEU mixed consumer cargo | AK38: MARINA | AL38: Web Portal | AM38: Verified | AN38: Container ship lost one generator set while queueing in the Manila Bay north approach anchorage lane. | AO38: 19:58 electrical load fluctuation; 20:05 generator trip; 20:09 redundancy restored and anchorage maintained. | AP38: Engineering watch redistributed loads and deferred movement until shore support cleared the vessel to continue. | AQ38: Inadequate Training | AR38: Mechanical Failure | AS38: Fuel contamination caused unstable generator performance under anchorage hotel load conditions. | AT38: Equipment Damage | AU38: 20 | AV38: 0 | AW38: 0 | AX38: 0 | AY38: Require fuel quality and standby-power checks for container vessels awaiting entry into Manila Bay. | AZ38: Generator Alarm Log | Fuel Sample Note | Anchorage Clearance

Sheet Lookups
A1: Lookup Tables
A2: Model assumptions and categorical mappings mirrored from the mockup logic.
A4: Province to Region | D4: Fallback Cause by Incident Type | G4: Fallback Behavior by Cause | J4: Fallback Cargo by Vessel Type | M4: Fallback Year Built by Vessel Type | P4: Severity Weights | T4: Season Order | U4: Visibility Order
A5: Province | B5: Region | D5: Incident Type | E5: Fallback Cause | G5: Cause | H5: Fallback Behavior | J5: Vessel Type | K5: Fallback Cargo | M5: Vessel Type | N5: Fallback Year Built | P5: Severity | Q5: Weight | R5: Color | T5: Northeast Monsoon | U5: Good
A6: Metro Manila | B6: Luzon | D6: Collision | E6: Navigation Error | G6: Navigation Error | H6: Communication Failure | Violation of Procedures | J6: Ferry | K6: Passengers | M6: Ferry | N6: 2009 | P6: Very Serious | Q6: 4 | R6: #991B1B | T6: Transition Season | U6: Moderate
A7: Batangas | B7: Luzon | D7: Grounding | E7: Navigation Error | G7: Mechanical Failure | H7: Inadequate Training | J7: Fishing Vessel | K7: Fish Catch | M7: Fishing Vessel | N7: 2001 | P7: Serious | Q7: 3 | R7: #DC2626 | T7: Southwest Monsoon | U7: Poor
A8: Cebu | B8: Visayas | D8: Sinking | E8: Weather Conditions | G8: Weather Conditions | H8: Communication Failure | Violation of Procedures | J8: Container Ship | K8: Containers | M8: Container Ship | N8: 2010 | P8: Less Serious | Q8: 2 | R8: #F97316 | T8: Typhoon Season | U8: Very Poor
A9: Bohol | B9: Visayas | D9: Fire/Explosion | E9: Mechanical Failure | G9: Human Error | H9: Fatigue | Violation of Procedures | J9: Oil Tanker | K9: Fuel / Oil | M9: Oil Tanker | N9: 2007 | P9: Near Miss | Q9: 1 | R9: #F59E0B
A10: Albay | B10: Luzon | D10: Capsizing | E10: Weather Conditions | G10: Under Investigation | J10: Bulk Carrier | K10: Bulk Cargo | M10: Bulk Carrier | N10: 2005
A11: Davao del Sur | B11: Mindanao | D11: Flooding | E11: Mechanical Failure | J11: General Cargo | K11: General Cargo | M11: General Cargo | N11: 2008
A12: Leyte | B12: Visayas | D12: Swamping | E12: Weather Conditions | J12: Passenger Vessel | K12: Passengers | M12: Passenger Vessel | N12: 2012
A13: Southern Leyte | B13: Visayas | D13: Machinery Failure | E13: Mechanical Failure
A14: Palawan | B14: Luzon | D14: Person Overboard | E14: Human Error
A15: Cagayan | B15: Luzon | D15: Pollution Incident | E15: Mechanical Failure
A16: Oriental Mindoro | B16: Luzon
A17: Misamis Oriental | B17: Mindanao
A18: Sorsogon | B18: Luzon
A19: Iloilo | B19: Visayas

Sheet Enriched
A1: Enriched Incident Model
A2: Formula-driven transformation layer matching the mockup's derived analytics fields.
A4: Incident ID | B4: Incident DateTime | C4: Incident Type | D4: Severity | E4: Vessel Type | F4: Authority | G4: Status | H4: Province | I4: Sea Area Resolved | J4: Corridor Resolved | K4: Region | L4: Visibility | M4: Month Label | N4: Month Key | O4: Year | P4: Season | Q4: Primary Cause Resolved | R4: Crew Behavior Factors Resolved | S4: Cargo Type Resolved | T4: Vessel Age Years | U4: Fatalities | V4: Injuries | W4: Casualty Count | X4: Severity Weight | Y4: Risk Index | Z4: Registry ID Captured | AA4: Voyage Captured | AB4: Weather Captured | AC4: Route Label | AD4: Standardization Score | AE4: Linked Evidence Flag | AF4: Review Matured Flag | AG4: Narrative | AH4: Vessel Name | AI4: Latitude | AJ4: Longitude | AK4: Reporting Method
A5: =Raw_Incidents!A5 -> INC-2025-000101 | B5: =Raw_Incidents!B5 -> 45669.184 | C5: =Raw_Incidents!C5 -> Collision | D5: =Raw_Incidents!E5 -> Serious | E5: =Raw_Incidents!H5 -> Bulk Carrier | F5: =Raw_Incidents!AK5 -> MARINA | G5: =Raw_Incidents!AM5 -> Published | H5: =Raw_Incidents!V5 -> Metro Manila | I5: =IF(Raw_Incidents!W5<>"",Raw_Incidents!W5,Raw_Incidents!U5) -> Manila Bay | J5: =IF(Raw_Incidents!X5<>"",Raw_Incidents!X5,IF(Raw_Incidents!AH5<>"",Raw_Incidents!AH5,IF(AND(Raw_Incidents!AF5<>"",Raw_Incidents!AG5<>""),Raw_Incidents!AF5&" to "&Raw_Incidents!AG5,"Corridor pending"))) -> Manila Bay North Approach | K5: =IFERROR(INDEX(Lookups!$B$6:$B$19,MATCH(Raw_Incidents!V5,Lookups!$A$6:$A$19,0)),"National") -> Luzon | L5: =Raw_Incidents!AA5 -> Moderate | M5: =TEXT(B5,"mmm yy") -> Jan 25 | N5: =TEXT(B5,"yyyy-mm") -> 2025-01 | O5: =YEAR(B5) -> 2025 | P5: =IF(OR(MONTH(B5)=12,MONTH(B5)<=2),"Northeast Monsoon",IF(AND(MONTH(B5)>=3,MONTH(B5)<=5),"Transition Season",IF(AND(MONTH(B5)>=6,MONTH(B5)<=9),"Southwest Monsoon","Typhoon Season"))) -> Northeast Monsoon | Q5: =IF(Raw_Incidents!AR5<>"",Raw_Incidents!AR5,IFERROR(INDEX(Lookups!$E$6:$E$15,MATCH(C5,Lookups!$D$6:$D$15,0)),"Under Investigation")) -> Navigation Error | R5: =IF(Raw_Incidents!AQ5<>"",Raw_Incidents!AQ5,IFERROR(INDEX(Lookups!$H$6:$H$10,MATCH(Q5,Lookups!$G$6:$G$10,0)),"")) -> Communication Failure | Violation of Procedures | S5: =IF(Raw_Incidents!AI5<>"",Raw_Incidents!AI5,IFERROR(INDEX(Lookups!$K$6:$K$12,MATCH(E5,Lookups!$J$6:$J$12,0)),"General Cargo")) -> Bulk cargo | T5: =MAX(YEAR(TODAY())-IF(Raw_Incidents!R5<>"",Raw_Incidents!R5,IFERROR(INDEX(Lookups!$N$6:$N$12,MATCH(E5,Lookups!$M$6:$M$12,0)),2010)),0) -> 20 | U5: =Raw_Incidents!AW5 -> 0 | V5: =Raw_Incidents!AX5 -> 2 | W5: =U5+V5 -> 2 | X5: =IFERROR(INDEX(Lookups!$Q$6:$Q$9,MATCH(D5,Lookups!$P$6:$P$9,0)),1) -> 3 | Y5: =X5*MAX(W5,1) -> 6 | Z5: =--OR(Raw_Incidents!J5<>"",Raw_Incidents!K5<>"") -> 1 | AA5: =--AND(Raw_Incidents!AF5<>"",Raw_Incidents!AG5<>"") -> 1 | AB5: =--AND(ISNUMBER(Raw_Incidents!Y5),ISNUMBER(Raw_Incidents!Z5),Raw_Incidents!AA5<>"") -> 1 | AC5: =IF(Raw_Incidents!AH5<>"",Raw_Incidents!AH5,IF(AND(Raw_Incidents!AF5<>"",Raw_Incidents!AG5<>""),Raw_Incidents!AF5&" to "&Raw_Incidents!AG5,"Route pending")) -> Subic-Manila inbound traffic lane | AD5: =ROUND((--(B5<>"")+--(C5<>"")+--(D5<>"")+--(Raw_Incidents!S5<>"")+--(Raw_Incidents!T5<>"")+--(Raw_Incidents!U5<>"")+--(H5<>"")+AB5+--(Raw_Incidents!F5<>"")+--(Raw_Incidents!I5<>"")+Z5+AA5+--(Raw_Incidents!AI5<>"")+--(Raw_Incidents!AN5<>"")+--(F5<>""))/15*100,0) -> 100 | AE5: =--(Raw_Incidents!AZ5<>"") -> 1 | AF5: =--OR(G5="Verified",G5="Published") -> 1 | AG5: =Raw_Incidents!AN5 -> Bulk carrier made contact with a harbor support craft while inbound to Manila Bay under congested traffic conditions. | AH5: =Raw_Incidents!F5 -> MV Pacific Trader | AI5: =Raw_Incidents!S5 -> 14.663 | AJ5: =Raw_Incidents!T5 -> 120.762 | AK5: =Raw_Incidents!AL5 -> Web Portal
